<?xml version="1.0" encoding="utf-8"?>
<robot name="rm_description">
  <!-- 根链接：base_link -->
  <link name="base_link">
    <inertial>
      <origin xyz="-0.01122376076567 -0.00284794721579435 0.0119690762525294" rpy="0 0 0" />
      <mass value="5.57999874587428" />
      <inertia ixx="0.0105925160219661" ixy="1.29829829990516E-06" ixz="-2.51464106571176E-05"
               iyy="0.0172203234904464" iyz="-2.4863980167142E-06" izz="0.0233520578911697" />
    </inertial>
    <visual>
      <origin xyz="0 0 0" rpy="0 0 0" />
      <geometry>
        <mesh filename="package://rm_description/meshes/base_link.STL" />
      </geometry>
      <material name="">
        <color rgba="0.792156862745098 0.819607843137255 0.933333333333333 1" />
      </material>
    </visual>
    <collision>
      <origin xyz="0 0 0" rpy="0 0 0" />
      <geometry>
        <mesh filename="package://rm_description/meshes/base_link.STL" />
      </geometry>
    </collision>
  </link>


  <!-- 雷达 -->
  <link name="radar">
    <inertial>
      <origin xyz="8.3267E-17 3.0531E-16 -0.0049576" rpy="0 0 0" />
      <mass value="0.17859" />
      <inertia ixx="0.00038339" ixy="6.0429E-19" ixz="-1.0897E-21"
               iyy="0.00038339" iyz="1.6591E-21" izz="0.00076383" />
    </inertial>
    <visual>
      <origin xyz="0 0 0" rpy="0 0 0" />
      <geometry>
        <mesh filename="package://rm_description/meshes/radar.STL" />
      </geometry>
      <material name="">
        <color rgba="0.79216 0.81961 0.93333 1" />
      </material>
    </visual>
    <collision>
      <origin xyz="0 0 0" rpy="0 0 0" />
      <geometry>
        <mesh filename="package://rm_description/meshes/radar.STL" />
      </geometry>
    </collision>
  </link>
  <joint name="radar_joint" type="fixed">
    <origin xyz="0.1572 -0.1665 0.0922" rpy="0 0 0" />
    <parent link="base_link" />
    <child link="radar" />
  </joint>

  <!-- 机械臂连杆1 -->
  <link name="link1">
    <inertial>
      <origin xyz="7.5138E-05 0.027318 0.03997" rpy="0 0 0" />
      <mass value="0.5831" />
      <inertia ixx="0.0005856" ixy="4.8904E-09" ixz="-9.2102E-09"
               iyy="0.00098372" iyz="8.5229E-09" izz="0.00077233" />
    </inertial>
    <visual>
      <origin xyz="0 0 0" rpy="0 0 0" />
      <geometry>
        <mesh filename="package://rm_description/meshes/link1.STL" />
      </geometry>
      <material name="">
        <color rgba="0.79216 0.81961 0.93333 1" />
      </material>
    </visual>
    <collision>
      <origin xyz="0 0 0" rpy="0 0 0" />
      <geometry>
        <mesh filename="package://rm_description/meshes/link1.STL" />
      </geometry>
    </collision>
  </link>
  <joint name="joint1" type="revolute">
    <origin xyz="0.0175 0 0.0977" rpy="0 0 0" />
    <parent link="base_link" />
    <child link="link1" />
    <axis xyz="0 0 1" />
    <limit lower="-3.14" upper="3.14" effort="20" velocity="6.28" />
  </joint>

  <!-- 机械臂连杆2 -->
  <link name="link2">
    <inertial>
      <origin xyz="0.0040084 0.15556 0.032129" rpy="0 0 0" />
      <mass value="0.54795" />
      <inertia ixx="0.0017176" ixy="3.7298E-08" ixz="-3.8163E-12"
               iyy="0.00025298" iyz="-1.4099E-06" izz="0.0018495" />
    </inertial>
    <visual>
      <origin xyz="0 0 0" rpy="0 0 0" />
      <geometry>
        <mesh filename="package://rm_description/meshes/link2.STL" />
      </geometry>
      <material name="">
        <color rgba="1 1 1 1" />
      </material>
    </visual>
    <collision>
      <origin xyz="0 0 0" rpy="0 0 0" />
      <geometry>
        <mesh filename="package://rm_description/meshes/link2.STL" />
      </geometry>
    </collision>
  </link>
  <joint name="joint2" type="revolute">
    <origin xyz="0 0.063 0.075" rpy="1.5708 -1.0472 0" />
    <parent link="link1" />
    <child link="link2" />
    <axis xyz="0 0 1" />
    <limit lower="-1.54" upper="0.0" effort="40" velocity="6.28" />
  </joint>

  <!-- 机械臂连杆3 -->
  <link name="link3">
    <inertial>
      <origin xyz="0.011856 -0.05002 0.0066166" rpy="0 0 0" />
      <mass value="0.79125" />
      <inertia ixx="0.00089963" ixy="9.0892E-05" ixz="5.0297E-07"
               iyy="0.00050087" iyz="1.3258E-06" izz="0.0010218" />
    </inertial>
    <visual>
      <origin xyz="0 0 0" rpy="0 0 0" />
      <geometry>
        <mesh filename="package://rm_description/meshes/link3.STL" />
      </geometry>
      <material name="">
        <color rgba="0.79216 0.81961 0.93333 1" />
      </material>
    </visual>
    <collision>
      <origin xyz="0 0 0" rpy="0 0 0" />
      <geometry>
        <mesh filename="package://rm_description/meshes/link3.STL" />
      </geometry>
    </collision>
  </link>
  <joint name="joint3" type="revolute">
    <origin xyz="0 0.295 0.12075" rpy="3.1416 0 -2.7925" />
    <parent link="link2" />
    <child link="link3" />
    <axis xyz="0 0 1" />
    <limit lower="-2.4" upper="0.0" effort="30" velocity="6.28" />
  </joint>

  <!-- 相机1 -->
  <link name="camera1">
    <inertial>
      <origin xyz="-0.034482 -0.00015312 0.0032629" rpy="0 0 0" />
      <mass value="0.036897" />
      <inertia ixx="1.6058E-05" ixy="-1.7376E-07" ixz="-1.7114E-06"
               iyy="2.9168E-05" iyz="-2.0999E-08" izz="3.5855E-05" />
    </inertial>
    <visual>
      <origin xyz="0 0 0" rpy="0 0 0" />
      <geometry>
        <mesh filename="package://rm_description/meshes/camera1.STL" />
      </geometry>
      <material name="">
        <color rgba="1 1 1 1" />
      </material>
    </visual>
    <collision>
      <origin xyz="0 0 0" rpy="0 0 0" />
      <geometry>
        <mesh filename="package://rm_description/meshes/camera1.STL" />
      </geometry>
    </collision>
  </link>
  <joint name="camera1_joint" type="fixed">
    <origin xyz="-0.062239 -0.0553 0" rpy="1.5708 0 -1.5708" />
    <parent link="link3" />
    <child link="camera1" />
  </joint>

  <!-- 相机2 -->
  <link name="camera2">
    <inertial>
      <origin xyz="-0.018394 -6.7298E-05 -0.0038392" rpy="0 0 0" />
      <mass value="0.057089" />
      <inertia ixx="0.0001312" ixy="1.2086E-07" ixz="1.739E-06"
               iyy="1.9438E-05" iyz="-2.9214E-08" izz="0.0001316" />
    </inertial>
    <visual>
      <origin xyz="0 0 0" rpy="0 0 0" />
      <geometry>
        <mesh filename="package://rm_description/meshes/camera2.STL" />
      </geometry>
      <material name="">
        <color rgba="0.37647 0.37647 0.37647 1" />
      </material>
    </visual>
    <collision>
      <origin xyz="0 0 0" rpy="0 0 0" />
      <geometry>
        <mesh filename="package://rm_description/meshes/camera2.STL" />
      </geometry>
    </collision>
  </link>
  <joint name="joint_camera2" type="fixed">
    <origin xyz="-0.03975 -0.13945 0" rpy="1.5708 0.0099997 -1.5708" />
    <parent link="link3" />
    <child link="camera2" />
  </joint>

  <!-- 机械臂连杆4 -->
  <link name="link4">
    <inertial>
      <origin xyz="-0.0046535 3.2003E-05 0.076088" rpy="0 0 0" />
      <mass value="0.32643" />
      <inertia ixx="0.00053041" ixy="-1.5339E-08" ixz="-7.1647E-09"
               iyy="0.00046136" iyz="-9.1966E-08" izz="0.00012164" />
    </inertial>
    <visual>
      <origin xyz="0 0 0" rpy="0 0 0" />
      <geometry>
        <mesh filename="package://rm_description/meshes/link4.STL" />
      </geometry>
      <material name="">
        <color rgba="1 1 1 1" />
      </material>
    </visual>
    <collision>
      <origin xyz="0 0 0" rpy="0 0 0" />
      <geometry>
        <mesh filename="package://rm_description/meshes/link4.STL" />
      </geometry>
    </collision>
  </link>
  <joint name="joint4" type="continuous"> <!-- 修复：改为continuous关节 -->
    <origin xyz="0.0245 -0.1555 0" rpy="1.5708 -1.5708 0" />
    <parent link="link3" />
    <child link="link4" />
    <axis xyz="0 0 1" />
    <limit lower="-3.0" upper="3.0" effort="3" velocity="6.28" />
  </joint>

  <!-- 机械臂连杆5 -->
  <link name="link5">
    <inertial>
      <origin xyz="-5.188E-05 0.014864 0.00048766" rpy="0 0 0" />
      <mass value="0.15797" />
      <inertia ixx="5.5994E-05" ixy="-4.1662E-08" ixz="-2.8517E-08"
               iyy="7.3422E-05" iyz="-1.6397E-07" izz="5.3618E-05" />
    </inertial>
    <visual>
      <origin xyz="0 0 0" rpy="0 0 0" />
      <geometry>
        <mesh filename="package://rm_description/meshes/link5.STL" />
      </geometry>
      <material name="">
        <color rgba="0.79216 0.81961 0.93333 1" />
      </material>
    </visual>
    <collision>
      <origin xyz="0 0 0" rpy="0 0 0" />
      <geometry>
        <mesh filename="package://rm_description/meshes/link5.STL" />
      </geometry>
    </collision>
  </link>
  <joint name="joint5" type="revolute">
    <origin xyz="0 0 0.1725" rpy="1.5708 0 -1.5708" />
    <parent link="link4" />
    <child link="link5" />
    <axis xyz="0 0 -1" />
    <limit lower="-1.57" upper="1.57" effort="9" velocity="6.28" />
  </joint>

  <!-- 机械臂连杆6 -->
  <link name="link6">
    <inertial>
      <origin xyz="-6.5465E-07 -3.2249E-05 0.051478" rpy="0 0 0" />
      <mass value="0.24205" />
      <inertia ixx="0.00024097" ixy="-2.7196E-08" ixz="5.3122E-10"
               iyy="6.561E-05" iyz="-4.1833E-08" izz="0.00027744" />
    </inertial>
    <visual>
      <origin xyz="0 0 0" rpy="0 0 0" />
      <geometry>
        <mesh filename="package://rm_description/meshes/link6.STL" />
      </geometry>
      <material name="">
        <color rgba="0.79216 0.81961 0.93333 1" />
      </material>
    </visual>
    <collision>
      <origin xyz="0 0 0" rpy="0 0 0" />
      <geometry>
        <mesh filename="package://rm_description/meshes/link6.STL" />
      </geometry>
    </collision>
  </link>
  <joint name="joint6" type="revolute">
    <origin xyz="0 0.035 -0.00115" rpy="-1.5708 0 0" />
    <parent link="link5" />
    <child link="link6" />
    <axis xyz="0 0 1" />
    <limit lower="-1.57" upper="1.57" effort="3" velocity="6.28" />
  </joint>

  <!-- 左夹爪 -->
  <link name="gripper_left">
    <inertial>
      <origin xyz="-0.00097623 -0.039906 -0.027286" rpy="0 0 0" />
      <mass value="0.082285" />
      <inertia ixx="6.4638E-05" ixy="1.1348E-08" ixz="4.7593E-08"
               iyy="1.8092E-05" iyz="-5.9634E-06" izz="5.465E-05" />
    </inertial>
    <visual>
      <origin xyz="0 0 0" rpy="0 0 0" />
      <geometry>
        <mesh filename="package://rm_description/meshes/gripper_left.STL" />
      </geometry>
      <material name="">
        <color rgba="0.79216 0.81961 0.93333 1" />
      </material>
    </visual>
    <collision>
      <origin xyz="0 0 0" rpy="0 0 0" />
      <geometry>
        <mesh filename="package://rm_description/meshes/gripper_left.STL" />
      </geometry>
    </collision>
  </link>
  <joint name="joint_gripper_left" type="prismatic">
    <origin xyz="0 -0.00115 0.1569" rpy="1.5708 0 0" />
    <parent link="link6" />
    <child link="gripper_left" />
    <axis xyz="0 0 -1" />
    <limit lower="0.0" upper="0.06" effort="1000" velocity="1.0" />
  </joint>

  <!-- 右夹爪 -->
  <link name="gripper_right">
    <inertial>
      <origin xyz="0.00097623 -0.03896 0.024986" rpy="0 0 0" />
      <mass value="0.082285" />
      <inertia ixx="6.4638E-05" ixy="-1.1348E-08" ixz="4.7593E-08"
               iyy="1.8092E-05" iyz="5.9634E-06" izz="5.465E-05" />
    </inertial>
    <visual>
      <origin xyz="0 0 0" rpy="0 0 0" />
      <geometry>
        <mesh filename="package://rm_description/meshes/gripper_right.STL" />
      </geometry>
      <material name="">
        <color rgba="0.79216 0.81961 0.93333 1" />
      </material>
    </visual>
    <collision>
      <origin xyz="0 0 0" rpy="0 0 0" />
      <geometry>
        <mesh filename="package://rm_description/meshes/gripper_right.STL" />
      </geometry>
    </collision>
  </link>
  <joint name="joint_gripper_right" type="prismatic">
    <origin xyz="0 -0.00115 0.1569" rpy="1.5708 0 0" />
    <parent link="link6" />
    <child link="gripper_right" />
    <axis xyz="0 0 -1" />
    <limit lower="-0.06" upper="0.0" effort="1000" velocity="1.0" />
  </joint>

  <!-- 虚拟底座：base_footprint -->
  <link name="base_footprint">
    <visual>
      <origin xyz="0 0 0" rpy="0 0 0" />
      <geometry>
        <box size="0.1 0.1 0.01" />
      </geometry>
      <material name="">
        <color rgba="1 1 1 0.5" />
      </material>
    </visual>
  </link>
  <joint name="joint_base_footprint" type="fixed">
    <origin xyz="0 0 0.18113" rpy="0 0 0" />
    <parent link="base_footprint" />
    <child link="base_link" />
  </joint>




  <ros2_control name="rm_description_ros2_control" type="system">
    <hardware>
        <plugin>mock_components/GenericSystem</plugin>
    </hardware>
    <joint name="joint1">
        <command_interface name="position"/>
        <state_interface name="position">
          <param name="initial_value">0.0</param>
        </state_interface>
        <state_interface name="velocity"/>
    </joint>
    <joint name="joint2">
        <command_interface name="position"/>
        <state_interface name="position">
          <param name="initial_value">0.0</param>
        </state_interface>
        <state_interface name="velocity"/>
    </joint>
    <joint name="joint3">
        <command_interface name="position"/>
        <state_interface name="position">
          <param name="initial_value">0.0</param>
        </state_interface>
        <state_interface name="velocity"/>
    </joint>
    <joint name="joint4">
        <command_interface name="position"/>
        <state_interface name="position">
          <param name="initial_value">0.0</param>
        </state_interface>
        <state_interface name="velocity"/>
    </joint>
    <joint name="joint5">
        <command_interface name="position"/>
        <state_interface name="position">
          <param name="initial_value">0.0</param>
        </state_interface>
        <state_interface name="velocity"/>
    </joint>
    <joint name="joint6">
        <command_interface name="position"/>
        <state_interface name="position">
          <param name="initial_value">0.0</param>
        </state_interface>
        <state_interface name="velocity"/>
    </joint>
    <joint name="joint_gripper_left">
        <command_interface name="position"/>
        <state_interface name="position">
          <param name="initial_value">0.0</param>
        </state_interface>
        <state_interface name="velocity"/>
    </joint>
    <joint name="joint_gripper_right">
        <command_interface name="position"/>
        <state_interface name="position">
          <param name="initial_value">0.0</param>
        </state_interface>
        <state_interface name="velocity"/>
    </joint>
  </ros2_control>
</robot>
